<?xml version="1.0"?>

 
<robot xmlns:xacro="http://www.ros.org/wiki/xacro" name="my_robot">

	<xacro:include filename="$(find soft_hand_description)/model/soft_hand.urdf.xacro"/>

	<material name="red">
	    <color rgba="255 0 0 1"/>
	</material>

	<material name="qbmove/flange">
		<color rgba="0.0 0.5 0.8 1.0"/>
	</material>

	<material name="qbmove/cube">
		<color rgba="0.35 0.35 0.35 1.0"/>
	</material>

	<material name="qbmove/shaft">
		<color rgba="0.8 0.8 0.8 1.0"/>
	</material>

	<material name="qbmove/default">
		<color rgba="0.35 0.35 0.35 1.0"/>
	</material>

	<material name="wheel">
		<color rgba="0.50 0.50 0.50 1.0"/>
	</material>



	<link name="base_link">
		<visual>
			<!--<material name="red"/>-->
			<geometry>
				<!--mesh filename="package://ego_description/meshes/Ego_body.stl" scale="0.001 0.001 0.001"/-->
				<box size="0.1 0.1 0.1"/>
			</geometry>
			<origin xyz="0 0 0.1" rpy="1.57075 -1.57075 0"/>
		</visual>
	</link>

	<link name="neck">
		<visual>
			<material name="qbmove/flange"/>
			<geometry>
				<mesh filename="package://ego_description/meshes/qb_c_flange.stl" scale="0.001 0.001 0.001"/>
			</geometry>
			<origin xyz="0 0 0" rpy="3.14 0 -1.57075"/>
		</visual>
	</link>

	<joint name="base_to_neck" type="continuous">
		    <axis xyz="0 0 1"/>
		    <origin rpy="0.0 0.0 0.0" xyz="0 0 0.74"/> 
		    <parent link="base_link"/>
		    <child link="neck"/>
	</joint>

	<link name="head">
		<visual>
			<material name="qbmove/cube"/>
			<geometry>
				<mesh filename="package://ego_description/meshes/Ego_head.stl" scale="0.001 0.001 0.001"/>
			</geometry>
			<origin xyz="0 0 0" rpy="1.57075 -1.57075 0"/>
		</visual>
	</link>

	<joint name="neck_to_head" type="continuous">
		    <axis xyz="0 1 0"/>
		    <origin rpy="0.0 0.0 0.0" xyz="0 0 0.058"/> 
		    <parent link="neck"/>
		    <child link="head"/>
	</joint>

	<!-- cubi -->
	<xacro:macro name="cube_shoulder" params="prefix reflect" >
	    <link name="${prefix}_shoulder_flange">
	        <visual>
	        	<material name="qbmove/flange"/>
	            <geometry>
	                <mesh filename="package://ego_description/meshes/qb_flat_flange.stl" scale="0.001 0.001 0.001"/>
	            </geometry>
	            <origin xyz="0 0 -0.033" rpy="0 0 0"/>
	        </visual>
	    </link>

	    <link name="${prefix}_shoulder_cube">
	        <visual>
	        	<material name="qbmove/cube"/>
	            <geometry>
	                <mesh filename="package://ego_description/meshes/qbmove_frame.stl" scale="0.001 0.001 0.001"/>
	            </geometry>
	            <origin xyz="-0.033 0 0" rpy="0 1.57075 0"/>
	        </visual>
	    </link>

	    <joint name="base_to_${prefix}_shoulder" type="revolute">
	    	<axis xyz="0 0 1"/>
			<limit effort="1000.0" lower="-3.14" upper="3.14" velocity="0.5"/>
			<origin xyz="0.025 ${reflect*-0.184} ${0.658+0.063}" rpy="${reflect*1.3951} 0.0 ${reflect*0.1737}"/>
	        <parent link="base_link"/>
	        <child link="${prefix}_shoulder_flange"/>
	    </joint>

	    <joint name="${prefix}_shoulder_flange_to_cube" type="fixed">
	        <parent link="${prefix}_shoulder_flange"/>
	        <child link="${prefix}_shoulder_cube"/>
	    </joint>
	</xacro:macro>

	<xacro:macro name="cube_arm" params="prefix reflect" >
	    <link name="${prefix}_arm_flage">
	        <visual>
	        	<material name="qbmove/flange"/>
	            <geometry>
	                <mesh filename="package://ego_description/meshes/qb_c_flange.stl" scale="0.001 0.001 0.001"/>
	            </geometry>
	            <origin xyz="0 ${reflect*(0.033-0.09)} 0" rpy="${reflect*1.57075} 0 0"/>
	        </visual>
	    </link>

	    <link name="${prefix}_arm_cube">
	        <visual>
	        	<material name="qbmove/cube"/>
	            <geometry>
	                <mesh filename="package://ego_description/meshes/qbmove_frame.stl" scale="0.001 0.001 0.001"/>
	            </geometry>
	            <origin xyz="0 ${reflect*(0.033-0.09)} 0" rpy="${reflect*1.57075} 3.14 0"/>
	        </visual>
	        <visual>
	            <geometry>
	                <mesh filename="package://ego_description/meshes/qbmove_pulley.stl" scale="0.001 0.001 0.001"/>
	            </geometry>
	            <origin xyz="0.025 ${reflect*(0.09-0.09)} 0" rpy="0 0 -1.57075"/>
	        </visual>
	    </link>

	    <joint name="shoulder_to_${prefix}_arm" type="revolute">
	    	<axis xyz="1 0 0"/>
			<limit effort="1000.0" lower="-3.14" upper="3.14" velocity="0.5"/>
			<origin xyz="0.0 0 0" rpy="0 0.0 0"/>
	        <parent link="${prefix}_shoulder_cube"/>
	        <child link="${prefix}_arm_flage"/>
	    </joint>

	    <joint name="${prefix}_arm_flage_to_cube" type="fixed">
	        <parent link="${prefix}_arm_flage"/>
	        <child link="${prefix}_arm_cube"/>
	    </joint>
	</xacro:macro>

	<xacro:macro name="cube_elbow" params="prefix reflect" >
	    <link name="${prefix}_elbow_flange">
	        <visual>
	        	<material name="qbmove/flange"/>
	            <geometry>
	                <mesh filename="package://ego_description/meshes/qb_flat_flange.stl" scale="0.001 0.001 0.001"/>
	            </geometry>
	            <origin xyz="0 ${reflect*0.033} 0" rpy="${reflect*1.57075} 1.57075 0"/>
	        </visual>
	    </link>

	    <link name="${prefix}_elbow_cube">
	        <visual>
	        	<material name="qbmove/cube"/>
	            <geometry>
	                <mesh filename="package://ego_description/meshes/qbmove_frame.stl" scale="0.001 0.001 0.001"/>
	            </geometry>
	            <origin xyz="0 0 -0.033" rpy="0 0 3.14"/>
	        </visual>

	        <visual>
	            <geometry>
	                <mesh filename="package://ego_description/meshes/qbmove_pulley.stl" scale="0.001 0.001 0.001"/>
	            </geometry>
	            <origin xyz="0 ${reflect*0.053} 0" rpy="0 0 ${(reflect+1)*(3.14/2)}"/>
	        </visual>
	    </link>

	    <joint name="arm_to_${prefix}_elbow" type="revolute">
	    	<axis xyz="0 1 0"/>
			<limit effort="1000.0" lower="-3.14" upper="3.14" velocity="0.5"/>
			<origin rpy="0.0 0.0 0.0" xyz="0.0 ${reflect*-0.168} 0.0"/>
	        <parent link="${prefix}_arm_cube"/>
	        <child link="${prefix}_elbow_flange"/>
	    </joint>

	    <joint name="${prefix}_elbow_flage_to_cube" type="fixed">
	        <parent link="${prefix}_elbow_flange"/>
	        <child link="${prefix}_elbow_cube"/>
	    </joint>
	</xacro:macro>

	<xacro:macro name="cube_forearm" params="prefix reflect" >
	    <link name="${prefix}_forearm_flange">
	        <visual>
	        	<material name="qbmove/flange"/>
	            <geometry>
	                <mesh filename="package://ego_description/meshes/qb_c_flange.stl" scale="0.001 0.001 0.001"/>
	            </geometry>
	            <origin xyz="0 ${reflect*(0.033-0.09)} 0" rpy="${reflect*1.57075} -1.57075 0"/>
	        </visual>
	    </link>

	    <link name="${prefix}_forearm_cube">
	        <visual>
	        	<material name="qbmove/cube"/>
	            <geometry>
	                <mesh filename="package://ego_description/meshes/qbmove_frame.stl" scale="0.001 0.001 0.001"/>
	            </geometry>
	            <origin xyz="0 ${reflect*(0.033-0.09)} 0" rpy="${reflect*1.57075} 3.14 0"/>
	        </visual>

	        <visual>
	            <geometry>
	                <mesh filename="package://ego_description/meshes/qbmove_pulley.stl" scale="0.001 0.001 0.001"/>
	            </geometry>
	            <origin xyz="0 0 0.025" rpy="1.57075 0 0"/>
	        </visual>
	    </link>

	    <joint name="elbow_to_${prefix}_forearm" type="revolute">
	    	<axis xyz="0 0 1"/>
			<limit effort="1000.0" lower="-3.14" upper="3.14" velocity="0.5"/>
			<origin xyz="0.0 0 0" rpy="0 0.0 0"/>
	        <parent link="${prefix}_elbow_cube"/>
	        <child link="${prefix}_forearm_flange"/>
	    </joint>

	    <joint name="${prefix}_forearm_flange_to_cube" type="fixed">
	        <parent link="${prefix}_forearm_flange"/>
	        <child link="${prefix}_forearm_cube"/>
	    </joint>
	</xacro:macro>

	<xacro:macro name="EE" params="prefix reflect" >
	    <link name="${prefix}_EE_flange">
	        <visual>
	        	<material name="qbmove/flange"/>
	            <geometry>
	                <mesh filename="package://ego_description/meshes/qb_flat_flange.stl" scale="0.001 0.001 0.001"/>
	            </geometry>
	            <origin xyz="0 ${reflect*0.033} 0" rpy="${reflect*1.57075} 1.57075 0"/>
	        </visual>
	    </link>

	    <joint name="forearm_to_${prefix}_EE" type="revolute">
	    	<axis xyz="0 1 0"/>
			<limit effort="1000.0" lower="-3.14" upper="3.14" velocity="0.5"/>
			<origin rpy="0.0 0.0 0.0" xyz="0.0 ${reflect*-0.168} 0.0"/>
	        <parent link="${prefix}_forearm_cube"/>
	        <child link="${prefix}_EE_flange"/>
	    </joint>

	</xacro:macro>




	<!-- Ego Left Arm -->
	<xacro:cube_shoulder prefix="left" reflect="-1"/>
	<xacro:cube_arm prefix="left" reflect="-1"/>
	<xacro:cube_elbow prefix="left" reflect="-1"/>
	<xacro:cube_forearm prefix="left" reflect="-1"/>
	<xacro:EE prefix="left" reflect="-1"/>

	<!-- LEFT SOFTHAND -->
	<xacro:soft_hand parent="left_EE_flange" name="left_hand" left="true" withAdaptiveTransmission="true" useMimicTag="true">
	    <origin xyz="0 -0.05 0" rpy="-1.57075 1.57075 0"/>
	</xacro:soft_hand>


	<!-- Ego Right Arm -->
	<xacro:cube_shoulder prefix="right" reflect="1"/>
	<xacro:cube_arm prefix="right" reflect="1"/>
	<xacro:cube_elbow prefix="right" reflect="1"/>
	<xacro:cube_forearm prefix="right" reflect="1"/>
	<xacro:EE prefix="right" reflect="1"/>
	<!-- RIGHT SOFTHAND -->
	<xacro:soft_hand parent="right_EE_flange" name="right_hand" left="false" withAdaptiveTransmission="true" useMimicTag="true">
	    <origin xyz="0 0.05 0" rpy="1.57075 1.57075 0"/>
	</xacro:soft_hand>


	
<!-- Ego Left Wheel-->

	<link name="wheel_L">
		<visual>
			<material name="wheel"/>
			<geometry>
				<!--<cylinder  length="0.1" radius="0.13"/>-->
				<mesh filename="package://ego_description/meshes/Ego_wheel.stl" scale="0.001 0.001 0.001"/>
			</geometry>
			<origin xyz="0 0 0" rpy="1.57075 0 0"/>
		</visual>
	</link>

	<joint name="L_joint_baseW" type="continuous">
		    <axis xyz="0 1 0"/>
		    <origin rpy="0.0 0.0 0.0" xyz="0.0 0.248 0.0"/> 
		    <parent link="base_link"/>
		    <child link="wheel_L"/>
	</joint>

<!-- Ego Right Wheel-->

	<link name="wheel_R">
		<visual>
			<material name="wheel"/>
			<geometry>
				<!--<cylinder  length="0.1" radius="0.13"/>-->
				<mesh filename="package://ego_description/meshes/Ego_wheel.stl" scale="0.001 0.001 0.001"/>
			</geometry>
			<origin xyz="0 0 0" rpy="1.57075 0 0"/>
		</visual>
	</link>

	<joint name="R_joint_baseW" type="continuous">
		    <axis xyz="0 1 0"/>
		    <origin rpy="0.0 0.0 0.0" xyz="0.0 -0.248 0.0"/> 
		    <parent link="base_link"/>
		    <child link="wheel_R"/>
	</joint>






	




</robot>